Traceback (most recent call last):
  File "/Users/lilelin/opt/anaconda3/envs/jupyterbook/lib/python3.11/site-packages/jupyter_cache/executors/utils.py", line 58, in single_nb_execution
    executenb(
  File "/Users/lilelin/opt/anaconda3/envs/jupyterbook/lib/python3.11/site-packages/nbclient/client.py", line 1305, in execute
    return NotebookClient(nb=nb, resources=resources, km=km, **kwargs).execute()
           ^^^^^^^^^^^^^^^^^^^^^^^^^^^^^^^^^^^^^^^^^^^^^^^^^^^^^^^^^^^^^^^^^^^^^
  File "/Users/lilelin/opt/anaconda3/envs/jupyterbook/lib/python3.11/site-packages/jupyter_core/utils/__init__.py", line 166, in wrapped
    return loop.run_until_complete(inner)
           ^^^^^^^^^^^^^^^^^^^^^^^^^^^^^^
  File "/Users/lilelin/opt/anaconda3/envs/jupyterbook/lib/python3.11/asyncio/base_events.py", line 653, in run_until_complete
    return future.result()
           ^^^^^^^^^^^^^^^
  File "/Users/lilelin/opt/anaconda3/envs/jupyterbook/lib/python3.11/site-packages/nbclient/client.py", line 705, in async_execute
    await self.async_execute_cell(
  File "/Users/lilelin/opt/anaconda3/envs/jupyterbook/lib/python3.11/site-packages/nbclient/client.py", line 1058, in async_execute_cell
    await self._check_raise_for_error(cell, cell_index, exec_reply)
  File "/Users/lilelin/opt/anaconda3/envs/jupyterbook/lib/python3.11/site-packages/nbclient/client.py", line 914, in _check_raise_for_error
    raise CellExecutionError.from_cell_and_msg(cell, exec_reply_content)
nbclient.exceptions.CellExecutionError: An error occurred while executing the following cell:
------------------
gv['date'] = pd.to_datetime(gv['date'])

gv13 = gv[gv['date'].dt.year == 2013]
gv14 = gv[gv['date'].dt.year == 2014]
gv15 = gv[gv['date'].dt.year == 2015]
gv16 = gv[gv['date'].dt.year == 2016]
gv17 = gv[gv['date'].dt.year == 2017]

x = [2013, 2014, 2015, 2016, 2017]
y = [len(gv13), len(gv14), len(gv15), len(gv16), len(gv17)]

fig = go.Figure(data=go.Scatter(x=x, y=y, mode='lines'))
fig.update_xaxes(
    ticktext=x,
    tickvals=[x[i] for i in range(len(x))],
    tickmode='array',
)

fig.update_layout(xaxis_title='Jaar<br><br>Figuur 1. Toename van schietincidenten in de VS in verloop van jaar<br><br><sup>De y-as geeft het aantal schietincidenten weer per tienduizenden. De x-as geeft de periode 2013-2017 in jaren weer.<br>In de periode van 2013-2017 is het aantal schietincidenten in de VS toegenomen. Een uitschieter is het jaar 2013, <br>omdat de organisatie in dit jaar begon met het bijhouden van schietincidenten.</br></sup>', 
                  yaxis_title='Aantal schietincidenten'
)

fig.show()
------------------


[0;31m---------------------------------------------------------------------------[0m
[0;31mKeyError[0m                                  Traceback (most recent call last)
File [0;32m~/opt/anaconda3/envs/jupyterbook/lib/python3.11/site-packages/pandas/core/indexes/base.py:3652[0m, in [0;36mIndex.get_loc[0;34m(self, key)[0m
[1;32m   3651[0m [38;5;28;01mtry[39;00m:
[0;32m-> 3652[0m     [38;5;28;01mreturn[39;00m [38;5;28;43mself[39;49m[38;5;241;43m.[39;49m[43m_engine[49m[38;5;241;43m.[39;49m[43mget_loc[49m[43m([49m[43mcasted_key[49m[43m)[49m
[1;32m   3653[0m [38;5;28;01mexcept[39;00m [38;5;167;01mKeyError[39;00m [38;5;28;01mas[39;00m err:

File [0;32m~/opt/anaconda3/envs/jupyterbook/lib/python3.11/site-packages/pandas/_libs/index.pyx:147[0m, in [0;36mpandas._libs.index.IndexEngine.get_loc[0;34m()[0m

File [0;32m~/opt/anaconda3/envs/jupyterbook/lib/python3.11/site-packages/pandas/_libs/index.pyx:176[0m, in [0;36mpandas._libs.index.IndexEngine.get_loc[0;34m()[0m

File [0;32mpandas/_libs/hashtable_class_helper.pxi:7080[0m, in [0;36mpandas._libs.hashtable.PyObjectHashTable.get_item[0;34m()[0m

File [0;32mpandas/_libs/hashtable_class_helper.pxi:7088[0m, in [0;36mpandas._libs.hashtable.PyObjectHashTable.get_item[0;34m()[0m

[0;31mKeyError[0m: 'date'

The above exception was the direct cause of the following exception:

[0;31mKeyError[0m                                  Traceback (most recent call last)
Cell [0;32mIn[3], line 1[0m
[0;32m----> 1[0m gv[[38;5;124m'[39m[38;5;124mdate[39m[38;5;124m'[39m] [38;5;241m=[39m pd[38;5;241m.[39mto_datetime([43mgv[49m[43m[[49m[38;5;124;43m'[39;49m[38;5;124;43mdate[39;49m[38;5;124;43m'[39;49m[43m][49m)
[1;32m      3[0m gv13 [38;5;241m=[39m gv[gv[[38;5;124m'[39m[38;5;124mdate[39m[38;5;124m'[39m][38;5;241m.[39mdt[38;5;241m.[39myear [38;5;241m==[39m [38;5;241m2013[39m]
[1;32m      4[0m gv14 [38;5;241m=[39m gv[gv[[38;5;124m'[39m[38;5;124mdate[39m[38;5;124m'[39m][38;5;241m.[39mdt[38;5;241m.[39myear [38;5;241m==[39m [38;5;241m2014[39m]

File [0;32m~/opt/anaconda3/envs/jupyterbook/lib/python3.11/site-packages/pandas/core/frame.py:3761[0m, in [0;36mDataFrame.__getitem__[0;34m(self, key)[0m
[1;32m   3759[0m [38;5;28;01mif[39;00m [38;5;28mself[39m[38;5;241m.[39mcolumns[38;5;241m.[39mnlevels [38;5;241m>[39m [38;5;241m1[39m:
[1;32m   3760[0m     [38;5;28;01mreturn[39;00m [38;5;28mself[39m[38;5;241m.[39m_getitem_multilevel(key)
[0;32m-> 3761[0m indexer [38;5;241m=[39m [38;5;28;43mself[39;49m[38;5;241;43m.[39;49m[43mcolumns[49m[38;5;241;43m.[39;49m[43mget_loc[49m[43m([49m[43mkey[49m[43m)[49m
[1;32m   3762[0m [38;5;28;01mif[39;00m is_integer(indexer):
[1;32m   3763[0m     indexer [38;5;241m=[39m [indexer]

File [0;32m~/opt/anaconda3/envs/jupyterbook/lib/python3.11/site-packages/pandas/core/indexes/base.py:3654[0m, in [0;36mIndex.get_loc[0;34m(self, key)[0m
[1;32m   3652[0m     [38;5;28;01mreturn[39;00m [38;5;28mself[39m[38;5;241m.[39m_engine[38;5;241m.[39mget_loc(casted_key)
[1;32m   3653[0m [38;5;28;01mexcept[39;00m [38;5;167;01mKeyError[39;00m [38;5;28;01mas[39;00m err:
[0;32m-> 3654[0m     [38;5;28;01mraise[39;00m [38;5;167;01mKeyError[39;00m(key) [38;5;28;01mfrom[39;00m [38;5;21;01merr[39;00m
[1;32m   3655[0m [38;5;28;01mexcept[39;00m [38;5;167;01mTypeError[39;00m:
[1;32m   3656[0m     [38;5;66;03m# If we have a listlike key, _check_indexing_error will raise[39;00m
[1;32m   3657[0m     [38;5;66;03m#  InvalidIndexError. Otherwise we fall through and re-raise[39;00m
[1;32m   3658[0m     [38;5;66;03m#  the TypeError.[39;00m
[1;32m   3659[0m     [38;5;28mself[39m[38;5;241m.[39m_check_indexing_error(key)

[0;31mKeyError[0m: 'date'

